Workbook

Sheet Summary
A1: LoRaWAN vs NB-IoT vs PoE — Cost & Fit Summary
A2: UK planning benchmark • GBP ex VAT • 5-year default • category scenarios are independently editable
A4: Model headline | D4: What the model says
A5: Categories modelled | B5: =COUNTA('Category Model'!A5:A21) -> 17 | D5: PoE is modelled as a third architecture, including endpoint hardware, cabling and installation, shared switch/network infrastructure, electricity, support and maintenance. People counting is now included: PoE is the natural fit for continuous ToF/camera/edge analytics, while LPWAN options are suitable only when endpoints transmit privacy-preserving aggregate counts. Blank device quantities remain deliberately unconfigured; enter units and sites in Category Model and replace blue assumptions with surveyed costs.
A6: Configured scenarios | B6: =COUNT('Category Model'!C5:C21) -> 1
A7: LoRaWAN lower-cost | B7: =COUNTIF(H13:H29,"LoRaWAN") -> 1
A8: NB-IoT lower-cost | B8: =COUNTIF(H13:H29,"NB-IoT") -> 0
A9: PoE lower-cost | B9: =COUNTIF(H13:H29,"PoE") -> 0
A10: Default horizon | B10: =Assumptions!B5 -> 5
A12: Sensor / use case | B12: LoRa fit | C12: NB fit | D12: PoE fit | E12: LoRa TCO/unit | F12: NB TCO/unit | G12: PoE TCO/unit | H12: Lowest-cost viable | I12: Technical recommendation | J12: Confidence | W12: Sensor / use case | X12: LoRaWAN | Y12: NB-IoT | Z12: PoE
A13: ='Category Model'!A5 -> IAQ sensors | B13: ='Category Model'!K5 -> 5 | C13: ='Category Model'!L5 -> 4 | D13: ='PoE Model'!H5 -> 5 | E13: ='Category Model'!U5 -> 284.05 | F13: ='Category Model'!Z5 -> 356 | G13: ='PoE Model'!P5 -> 314.6 | H13: =IF(COUNT('Category Model'!C5)=0,"Not modelled",IF(MAX(B13:D13)<=2,"Technical constraint",IF(IF(B13>=3,E13,1E+99)=MIN(IF(B13>=3,E13,1E+99),IF(C13>=3,F13,1E+99),IF(D13>=3,G13,1E+99)),"LoRaWAN",IF(IF(C13>=3,F13,1E+99)=MIN(IF(B13>=3,E13,1E+99),IF(C13>=3,F13,1E+99),IF(D13>=3,G13,1E+99)),"NB-IoT","PoE")))) -> LoRaWAN | I13: =IF(H13="PoE",'PoE Model'!J5,IF(H13="Not modelled","Enter device quantity in Category Model",'Category Model'!N5)) -> LoRaWAN for dense estates; NB-IoT for isolated buildings | J13: =IF(H13="PoE",'PoE Model'!K5,'Category Model'!O5) -> Medium | T13: =A13 -> IAQ sensors | U13: =D13 -> 5 | V13: =E13 -> 284.05 | W13: =A13 -> IAQ sensors | X13: =E13 -> 284.05 | Y13: =F13 -> 356 | Z13: =G13 -> 314.6
A14: ='Category Model'!A21 -> People counting / footfall | B14: ='Category Model'!K21 -> 4 | C14: ='Category Model'!L21 -> 4 | D14: ='PoE Model'!H21 -> 5 | E14: ='Category Model'!U21 | F14: ='Category Model'!Z21 | G14: ='PoE Model'!P21 | H14: =IF(COUNT('Category Model'!C21)=0,"Not modelled",IF(MAX(B14:D14)<=2,"Technical constraint",IF(IF(B14>=3,E14,1E+99)=MIN(IF(B14>=3,E14,1E+99),IF(C14>=3,F14,1E+99),IF(D14>=3,G14,1E+99)),"LoRaWAN",IF(IF(C14>=3,F14,1E+99)=MIN(IF(B14>=3,E14,1E+99),IF(C14>=3,F14,1E+99),IF(D14>=3,G14,1E+99)),"NB-IoT","PoE")))) -> Not modelled | I14: =IF(H14="PoE",'PoE Model'!J21,IF(H14="Not modelled","Enter device quantity in Category Model",'Category Model'!N21)) -> Enter device quantity in Category Model | J14: =IF(H14="PoE",'PoE Model'!K21,'Category Model'!O21) -> Medium | T14: =A14 -> People counting / footfall | W14: =A14 -> People counting / footfall | X14: =E14 | Y14: =F14 | Z14: =G14
A15: ='Category Model'!A6 -> Parking bay sensors | B15: ='Category Model'!K6 -> 5 | C15: ='Category Model'!L6 -> 5 | D15: ='PoE Model'!H6 -> 2 | E15: ='Category Model'!U6 | F15: ='Category Model'!Z6 | G15: ='PoE Model'!P6 | H15: =IF(COUNT('Category Model'!C6)=0,"Not modelled",IF(MAX(B15:D15)<=2,"Technical constraint",IF(IF(B15>=3,E15,1E+99)=MIN(IF(B15>=3,E15,1E+99),IF(C15>=3,F15,1E+99),IF(D15>=3,G15,1E+99)),"LoRaWAN",IF(IF(C15>=3,F15,1E+99)=MIN(IF(B15>=3,E15,1E+99),IF(C15>=3,F15,1E+99),IF(D15>=3,G15,1E+99)),"NB-IoT","PoE")))) -> Not modelled | I15: =IF(H15="PoE",'PoE Model'!J6,IF(H15="Not modelled","Enter device quantity in Category Model",'Category Model'!N6)) -> Enter device quantity in Category Model | J15: =IF(H15="PoE",'PoE Model'!K6,'Category Model'!O6) -> Medium | T15: =A15 -> Parking bay sensors | U15: =D15 -> 2 | V15: =E15 | W15: =A15 -> Parking bay sensors | X15: =E15 | Y15: =F15 | Z15: =G15
A16: ='Category Model'!A7 -> Room displays | B16: ='Category Model'!K7 -> 3 | C16: ='Category Model'!L7 -> 3 | D16: ='PoE Model'!H7 -> 5 | E16: ='Category Model'!U7 | F16: ='Category Model'!Z7 | G16: ='PoE Model'!P7 | H16: =IF(COUNT('Category Model'!C7)=0,"Not modelled",IF(MAX(B16:D16)<=2,"Technical constraint",IF(IF(B16>=3,E16,1E+99)=MIN(IF(B16>=3,E16,1E+99),IF(C16>=3,F16,1E+99),IF(D16>=3,G16,1E+99)),"LoRaWAN",IF(IF(C16>=3,F16,1E+99)=MIN(IF(B16>=3,E16,1E+99),IF(C16>=3,F16,1E+99),IF(D16>=3,G16,1E+99)),"NB-IoT","PoE")))) -> Not modelled | I16: =IF(H16="PoE",'PoE Model'!J7,IF(H16="Not modelled","Enter device quantity in Category Model",'Category Model'!N7)) -> Enter device quantity in Category Model | J16: =IF(H16="PoE",'PoE Model'!K7,'Category Model'!O7) -> Low | T16: =A16 -> Room displays | U16: =D16 -> 5 | V16: =E16 | W16: =A16 -> Room displays | X16: =E16 | Y16: =F16 | Z16: =G16
A17: ='Category Model'!A8 -> Lux sensors | B17: ='Category Model'!K8 -> 5 | C17: ='Category Model'!L8 -> 4 | D17: ='PoE Model'!H8 -> 5 | E17: ='Category Model'!U8 | F17: ='Category Model'!Z8 | G17: ='PoE Model'!P8 | H17: =IF(COUNT('Category Model'!C8)=0,"Not modelled",IF(MAX(B17:D17)<=2,"Technical constraint",IF(IF(B17>=3,E17,1E+99)=MIN(IF(B17>=3,E17,1E+99),IF(C17>=3,F17,1E+99),IF(D17>=3,G17,1E+99)),"LoRaWAN",IF(IF(C17>=3,F17,1E+99)=MIN(IF(B17>=3,E17,1E+99),IF(C17>=3,F17,1E+99),IF(D17>=3,G17,1E+99)),"NB-IoT","PoE")))) -> Not modelled | I17: =IF(H17="PoE",'PoE Model'!J8,IF(H17="Not modelled","Enter device quantity in Category Model",'Category Model'!N8)) -> Enter device quantity in Category Model | J17: =IF(H17="PoE",'PoE Model'!K8,'Category Model'!O8) -> Medium | T17: =A17 -> Lux sensors | U17: =D17 -> 5 | V17: =E17 | W17: =A17 -> Lux sensors | X17: =E17 | Y17: =F17 | Z17: =G17
A18: ='Category Model'!A9 -> Metering — electricity and water | B18: ='Category Model'!K9 -> 5 | C18: ='Category Model'!L9 -> 5 | D18: ='PoE Model'!H9 -> 4 | E18: ='Category Model'!U9 | F18: ='Category Model'!Z9 | G18: ='PoE Model'!P9 | H18: =IF(COUNT('Category Model'!C9)=0,"Not modelled",IF(MAX(B18:D18)<=2,"Technical constraint",IF(IF(B18>=3,E18,1E+99)=MIN(IF(B18>=3,E18,1E+99),IF(C18>=3,F18,1E+99),IF(D18>=3,G18,1E+99)),"LoRaWAN",IF(IF(C18>=3,F18,1E+99)=MIN(IF(B18>=3,E18,1E+99),IF(C18>=3,F18,1E+99),IF(D18>=3,G18,1E+99)),"NB-IoT","PoE")))) -> Not modelled | I18: =IF(H18="PoE",'PoE Model'!J9,IF(H18="Not modelled","Enter device quantity in Category Model",'Category Model'!N9)) -> Enter device quantity in Category Model | J18: =IF(H18="PoE",'PoE Model'!K9,'Category Model'!O9) -> High | T18: =A18 -> Metering — electricity and water | U18: =D18 -> 4 | V18: =E18 | W18: =A18 -> Metering — electricity and water | X18: =E18 | Y18: =F18 | Z18: =G18
A19: ='Category Model'!A10 -> Fridge / process temperature | B19: ='Category Model'!K10 -> 5 | C19: ='Category Model'!L10 -> 5 | D19: ='PoE Model'!H10 -> 4 | E19: ='Category Model'!U10 | F19: ='Category Model'!Z10 | G19: ='PoE Model'!P10 | H19: =IF(COUNT('Category Model'!C10)=0,"Not modelled",IF(MAX(B19:D19)<=2,"Technical constraint",IF(IF(B19>=3,E19,1E+99)=MIN(IF(B19>=3,E19,1E+99),IF(C19>=3,F19,1E+99),IF(D19>=3,G19,1E+99)),"LoRaWAN",IF(IF(C19>=3,F19,1E+99)=MIN(IF(B19>=3,E19,1E+99),IF(C19>=3,F19,1E+99),IF(D19>=3,G19,1E+99)),"NB-IoT","PoE")))) -> Not modelled | I19: =IF(H19="PoE",'PoE Model'!J10,IF(H19="Not modelled","Enter device quantity in Category Model",'Category Model'!N10)) -> Enter device quantity in Category Model | J19: =IF(H19="PoE",'PoE Model'!K10,'Category Model'!O10) -> High | T19: =A19 -> Fridge / process temperature | U19: =D19 -> 4 | V19: =E19 | W19: =A19 -> Fridge / process temperature | X19: =E19 | Y19: =F19 | Z19: =G19
A20: ='Category Model'!A11 -> Waste water monitoring | B20: ='Category Model'!K11 -> 4 | C20: ='Category Model'!L11 -> 5 | D20: ='PoE Model'!H11 -> 2 | E20: ='Category Model'!U11 | F20: ='Category Model'!Z11 | G20: ='PoE Model'!P11 | H20: =IF(COUNT('Category Model'!C11)=0,"Not modelled",IF(MAX(B20:D20)<=2,"Technical constraint",IF(IF(B20>=3,E20,1E+99)=MIN(IF(B20>=3,E20,1E+99),IF(C20>=3,F20,1E+99),IF(D20>=3,G20,1E+99)),"LoRaWAN",IF(IF(C20>=3,F20,1E+99)=MIN(IF(B20>=3,E20,1E+99),IF(C20>=3,F20,1E+99),IF(D20>=3,G20,1E+99)),"NB-IoT","PoE")))) -> Not modelled | I20: =IF(H20="PoE",'PoE Model'!J11,IF(H20="Not modelled","Enter device quantity in Category Model",'Category Model'!N11)) -> Enter device quantity in Category Model | J20: =IF(H20="PoE",'PoE Model'!K11,'Category Model'!O11) -> Medium | T20: =A20 -> Waste water monitoring | U20: =D20 -> 2 | V20: =E20 | W20: =A20 -> Waste water monitoring | X20: =E20 | Y20: =F20 | Z20: =G20
A21: ='Category Model'!A12 -> Water temperature | B21: ='Category Model'!K12 -> 5 | C21: ='Category Model'!L12 -> 5 | D21: ='PoE Model'!H12 -> 3 | E21: ='Category Model'!U12 | F21: ='Category Model'!Z12 | G21: ='PoE Model'!P12 | H21: =IF(COUNT('Category Model'!C12)=0,"Not modelled",IF(MAX(B21:D21)<=2,"Technical constraint",IF(IF(B21>=3,E21,1E+99)=MIN(IF(B21>=3,E21,1E+99),IF(C21>=3,F21,1E+99),IF(D21>=3,G21,1E+99)),"LoRaWAN",IF(IF(C21>=3,F21,1E+99)=MIN(IF(B21>=3,E21,1E+99),IF(C21>=3,F21,1E+99),IF(D21>=3,G21,1E+99)),"NB-IoT","PoE")))) -> Not modelled | I21: =IF(H21="PoE",'PoE Model'!J12,IF(H21="Not modelled","Enter device quantity in Category Model",'Category Model'!N12)) -> Enter device quantity in Category Model | J21: =IF(H21="PoE",'PoE Model'!K12,'Category Model'!O12) -> High | T21: =A21 -> Water temperature | U21: =D21 -> 3 | V21: =E21 | W21: =A21 -> Water temperature | X21: =E21 | Y21: =F21 | Z21: =G21
A22: ='Category Model'!A13 -> Water flow | B22: ='Category Model'!K13 -> 5 | C22: ='Category Model'!L13 -> 5 | D22: ='PoE Model'!H13 -> 3 | E22: ='Category Model'!U13 | F22: ='Category Model'!Z13 | G22: ='PoE Model'!P13 | H22: =IF(COUNT('Category Model'!C13)=0,"Not modelled",IF(MAX(B22:D22)<=2,"Technical constraint",IF(IF(B22>=3,E22,1E+99)=MIN(IF(B22>=3,E22,1E+99),IF(C22>=3,F22,1E+99),IF(D22>=3,G22,1E+99)),"LoRaWAN",IF(IF(C22>=3,F22,1E+99)=MIN(IF(B22>=3,E22,1E+99),IF(C22>=3,F22,1E+99),IF(D22>=3,G22,1E+99)),"NB-IoT","PoE")))) -> Not modelled | I22: =IF(H22="PoE",'PoE Model'!J13,IF(H22="Not modelled","Enter device quantity in Category Model",'Category Model'!N13)) -> Enter device quantity in Category Model | J22: =IF(H22="PoE",'PoE Model'!K13,'Category Model'!O13) -> High | T22: =A22 -> Water flow | U22: =D22 -> 3 | V22: =E22 | W22: =A22 -> Water flow | X22: =E22 | Y22: =F22 | Z22: =G22
A23: ='Category Model'!A14 -> Water leak detection | B23: ='Category Model'!K14 -> 5 | C23: ='Category Model'!L14 -> 5 | D23: ='PoE Model'!H14 -> 4 | E23: ='Category Model'!U14 | F23: ='Category Model'!Z14 | G23: ='PoE Model'!P14 | H23: =IF(COUNT('Category Model'!C14)=0,"Not modelled",IF(MAX(B23:D23)<=2,"Technical constraint",IF(IF(B23>=3,E23,1E+99)=MIN(IF(B23>=3,E23,1E+99),IF(C23>=3,F23,1E+99),IF(D23>=3,G23,1E+99)),"LoRaWAN",IF(IF(C23>=3,F23,1E+99)=MIN(IF(B23>=3,E23,1E+99),IF(C23>=3,F23,1E+99),IF(D23>=3,G23,1E+99)),"NB-IoT","PoE")))) -> Not modelled | I23: =IF(H23="PoE",'PoE Model'!J14,IF(H23="Not modelled","Enter device quantity in Category Model",'Category Model'!N14)) -> Enter device quantity in Category Model | J23: =IF(H23="PoE",'PoE Model'!K14,'Category Model'!O14) -> High | T23: =A23 -> Water leak detection | U23: =D23 -> 4 | V23: =E23 | W23: =A23 -> Water leak detection | X23: =E23 | Y23: =F23 | Z23: =G23
A24: ='Category Model'!A15 -> Acoustic sensors | B24: ='Category Model'!K15 -> 4 | C24: ='Category Model'!L15 -> 5 | D24: ='PoE Model'!H15 -> 4 | E24: ='Category Model'!U15 | F24: ='Category Model'!Z15 | G24: ='PoE Model'!P15 | H24: =IF(COUNT('Category Model'!C15)=0,"Not modelled",IF(MAX(B24:D24)<=2,"Technical constraint",IF(IF(B24>=3,E24,1E+99)=MIN(IF(B24>=3,E24,1E+99),IF(C24>=3,F24,1E+99),IF(D24>=3,G24,1E+99)),"LoRaWAN",IF(IF(C24>=3,F24,1E+99)=MIN(IF(B24>=3,E24,1E+99),IF(C24>=3,F24,1E+99),IF(D24>=3,G24,1E+99)),"NB-IoT","PoE")))) -> Not modelled | I24: =IF(H24="PoE",'PoE Model'!J15,IF(H24="Not modelled","Enter device quantity in Category Model",'Category Model'!N15)) -> Enter device quantity in Category Model | J24: =IF(H24="PoE",'PoE Model'!K15,'Category Model'!O15) -> Medium | T24: =A24 -> Acoustic sensors | U24: =D24 -> 4 | V24: =E24 | W24: =A24 -> Acoustic sensors | X24: =E24 | Y24: =F24 | Z24: =G24
A25: ='Category Model'!A16 -> Bin fill level — ultrasonic | B25: ='Category Model'!K16 -> 5 | C25: ='Category Model'!L16 -> 5 | D25: ='PoE Model'!H16 -> 2 | E25: ='Category Model'!U16 | F25: ='Category Model'!Z16 | G25: ='PoE Model'!P16 | H25: =IF(COUNT('Category Model'!C16)=0,"Not modelled",IF(MAX(B25:D25)<=2,"Technical constraint",IF(IF(B25>=3,E25,1E+99)=MIN(IF(B25>=3,E25,1E+99),IF(C25>=3,F25,1E+99),IF(D25>=3,G25,1E+99)),"LoRaWAN",IF(IF(C25>=3,F25,1E+99)=MIN(IF(B25>=3,E25,1E+99),IF(C25>=3,F25,1E+99),IF(D25>=3,G25,1E+99)),"NB-IoT","PoE")))) -> Not modelled | I25: =IF(H25="PoE",'PoE Model'!J16,IF(H25="Not modelled","Enter device quantity in Category Model",'Category Model'!N16)) -> Enter device quantity in Category Model | J25: =IF(H25="PoE",'PoE Model'!K16,'Category Model'!O16) -> High | T25: =A25 -> Bin fill level — ultrasonic | U25: =D25 -> 2 | V25: =E25 | W25: =A25 -> Bin fill level — ultrasonic | X25: =E25 | Y25: =F25 | Z25: =G25
A26: ='Category Model'!A17 -> Optical bin sensors / computer vision | B26: ='Category Model'!K17 -> 2 | C26: ='Category Model'!L17 -> 2 | D26: ='PoE Model'!H17 -> 5 | E26: ='Category Model'!U17 | F26: ='Category Model'!Z17 | G26: ='PoE Model'!P17 | H26: =IF(COUNT('Category Model'!C17)=0,"Not modelled",IF(MAX(B26:D26)<=2,"Technical constraint",IF(IF(B26>=3,E26,1E+99)=MIN(IF(B26>=3,E26,1E+99),IF(C26>=3,F26,1E+99),IF(D26>=3,G26,1E+99)),"LoRaWAN",IF(IF(C26>=3,F26,1E+99)=MIN(IF(B26>=3,E26,1E+99),IF(C26>=3,F26,1E+99),IF(D26>=3,G26,1E+99)),"NB-IoT","PoE")))) -> Not modelled | I26: =IF(H26="PoE",'PoE Model'!J17,IF(H26="Not modelled","Enter device quantity in Category Model",'Category Model'!N17)) -> Enter device quantity in Category Model | J26: =IF(H26="PoE",'PoE Model'!K17,'Category Model'!O17) -> Low | T26: =A26 -> Optical bin sensors / computer vision | U26: =D26 -> 5 | V26: =E26 | W26: =A26 -> Optical bin sensors / computer vision | X26: =E26 | Y26: =F26 | Z26: =G26
... A28: ='Category Model'!A19 -> Pressure sensors — medical gases | B28: ='Category Model'!K19 -> 4 | C28: ='Category Model'!L19 -> 4 | D28: ='PoE Model'!H19 -> 5 | E28: ='Category Model'!U19 | F28: ='Category Model'!Z19 | G28: ='PoE Model'!P19 | H28: =IF(COUNT('Category Model'!C19)=0,"Not modelled",IF(MAX(B28:D28)<=2,"Technical constraint",IF(IF(B28>=3,E28,1E+99)=MIN(IF(B28>=3,E28,1E+99),IF(C28>=3,F28,1E+99),IF(D28>=3,G28,1E+99)),"LoRaWAN",IF(IF(C28>=3,F28,1E+99)=MIN(IF(B28>=3,E28,1E+99),IF(C28>=3,F28,1E+99),IF(D28>=3,G28,1E+99)),"NB-IoT","PoE")))) -> Not modelled | I28: =IF(H28="PoE",'PoE Model'!J19,IF(H28="Not modelled","Enter device quantity in Category Model",'Category Model'!N19)) -> Enter device quantity in Category Model | J28: =IF(H28="PoE",'PoE Model'!K19,'Category Model'!O19) -> Low | T28: =A28 -> Pressure sensors — medical gases | U28: =D28 -> 5 | V28: =E28 | W28: =A28 -> Pressure sensors — medical gases | X28: =E28 | Y28: =F28 | Z28: =G28
A29: ='Category Model'!A20 -> Ultrasonic non-invasive — medical gases | B29: ='Category Model'!K20 -> 4 | C29: ='Category Model'!L20 -> 4 | D29: ='PoE Model'!H20 -> 5 | E29: ='Category Model'!U20 | F29: ='Category Model'!Z20 | G29: ='PoE Model'!P20 | H29: =IF(COUNT('Category Model'!C20)=0,"Not modelled",IF(MAX(B29:D29)<=2,"Technical constraint",IF(IF(B29>=3,E29,1E+99)=MIN(IF(B29>=3,E29,1E+99),IF(C29>=3,F29,1E+99),IF(D29>=3,G29,1E+99)),"LoRaWAN",IF(IF(C29>=3,F29,1E+99)=MIN(IF(B29>=3,E29,1E+99),IF(C29>=3,F29,1E+99),IF(D29>=3,G29,1E+99)),"NB-IoT","PoE")))) -> Not modelled | I29: =IF(H29="PoE",'PoE Model'!J20,IF(H29="Not modelled","Enter device quantity in Category Model",'Category Model'!N20)) -> Enter device quantity in Category Model | J29: =IF(H29="PoE",'PoE Model'!K20,'Category Model'!O20) -> Low | W29: =A29 -> Ultrasonic non-invasive — medical gases | X29: =E29 | Y29: =F29 | Z29: =G29

Sheet Assumptions
A1: LoRaWAN vs NB-IoT vs PoE — Planning Assumptions | B1: LoRaWAN vs NB-IoT — Planning Assumptions | C1: LoRaWAN vs NB-IoT — Planning Assumptions | D1: LoRaWAN vs NB-IoT — Planning Assumptions | E1: LoRaWAN vs NB-IoT — Planning Assumptions | F1: LoRaWAN vs NB-IoT — Planning Assumptions
A2: Blue cells are editable. Costs exclude VAT and the business application/dashboard layer common to all options. | B2: Blue cells are editable. Costs exclude VAT and the business application/dashboard layer common to both options. | C2: Blue cells are editable. Costs exclude VAT and the business application/dashboard layer common to both options. | D2: Blue cells are editable. Costs exclude VAT and the business application/dashboard layer common to both options. | E2: Blue cells are editable. Costs exclude VAT and the business application/dashboard layer common to both options. | F2: Blue cells are editable. Costs exclude VAT and the business application/dashboard layer common to both options.
A4: Driver | B4: Value | C4: Unit | D4: Basis | E4: Source / evidence | F4: Sensitivity note
A5: Analysis horizon | B5: 5 | C5: years | D5: Planning assumption | F5: Change to 3, 7 or 10 years as required
A6: Gateways per site | B6: 1 | C6: gateway/site | D6: Planning assumption | F6: Survey RF coverage; resilient designs may need 2+
A7: LoRaWAN gateway hardware | B7: 415.8 | C7: £/gateway | D7: Milesight UG65 UK price | E7: https://ukiot.io/shop/ | F7: Lower-cost gateways start around £190
A8: LoRaWAN gateway installation | B8: 300 | C8: £/gateway | D8: Planning allowance | F8: Includes mounting, power and network connection
A9: LoRaWAN gateway support | B9: 60 | C9: £/gateway/year | D9: Planning allowance | F9: Remote monitoring and firmware administration
A10: LoRaWAN gateway power | B10: 22 | C10: £/gateway/year | D10: 8 W at £0.31/kWh | F10: Remove if hosted power is immaterial
A11: LoRaWAN network server | B11: 0 | C11: £/device/month | D11: Planning benchmark at scale | E11: https://aws.amazon.com/marketplace/pp/prodview-djx65iyt6w5cy | F11: Small fleets can face a fixed minimum; embedded/open-source can be lower
A12: LoRaWAN fixed platform charge | B12: 0 | C12: £/deployment/year | D12: Assumes shared or embedded server | F12: Enter vendor minimum subscription if applicable
A13: LoRaWAN device commissioning | B13: 15 | C13: £/device | D13: Planning allowance | F13: Provisioning, keys, labelling and acceptance
A14: NB-IoT monthly connectivity | B14: 0.98 | C14: £/device/month | D14: User-provided tariff | F14: Applied for every month in the analysis horizon
A15: NB-IoT SIM / activation one-off fee | B15: 0.7 | C15: £/device | D15: User-provided tariff | F15: Charged once per device
A16: NB-IoT included data | B16: 17 | C16: MB/device/month | D16: User-provided tariff | F16: Monthly allowance; overage is charged separately
A17: NB-IoT data overage | B17: 0.01 | C17: £/MB | D17: User-provided tariff | F17: Applied to monthly usage above 17 MB per device
A18: NB-IoT device commissioning | B18: 12 | C18: £/device | D18: Planning allowance | F18: SIM/eSIM activation and acceptance
A19: Annual device maintenance | B19: 2 | C19: % of hardware/year | D19: Planning allowance | F19: Excludes calibration regimes unique to the sensing application
A20: Battery service visit | B20: 35 | C20: £/device/event | D20: Planning allowance | F20: Set higher for traffic management, confined space or clinical access
A21: EUR to GBP | B21: 0.85388 | C21: £/€ | D21: ECB, 24 Jul 2026 | E21: https://www.ecb.europa.eu/stats/policy_and_exchange_rates/euro_reference_exchange_rates/html/index.en.html | F21: Update for procurement date
A22: PoE switch/network hardware | B22: 0 | C22: £/site | D22: Planning allowance | F22: Use only incremental switch/UPS capacity attributable to this deployment
A23: PoE switch/network installation | B23: 0 | C23: £/site | D23: Planning allowance | F23: Rack, patching, configuration and acceptance; excludes major comms-room works
A24: PoE switch/network support | B24: 0 | C24: £/site/year | D24: Planning allowance | F24: Monitoring, firmware and replacement allowance
A25: PoE endpoint commissioning | B25: 20 | C25: £/device | D25: Planning allowance | F25: Port configuration, labelling, test and handover
A26: Electricity price | B26: 0.28 | C26: £/kWh | D26: Planning allowance | F26: Update to the organisation's delivered electricity rate
A27: PoE power delivery efficiency | B27: 0.9 | C27: % | D27: Planning allowance | E27: https://ethernetalliance.org/wp-content/uploads/2019/12/WP_EA_Overview8023bt_V2p1_FINAL.pdf | F27: Use measured PSE/cabling efficiency where available
A28: PoE endpoint maintenance | B28: 0.01 | C28: % of hardware/year | D28: Planning allowance | F28: Endpoint-only allowance; switch support is modelled separately

Sheet Category Model
A1: Category-Level Five-Year TCO | B1: Category-Level Five-Year TCO | C1: Category-Level Five-Year TCO | D1: Category-Level Five-Year TCO | E1: Category-Level Five-Year TCO | F1: Category-Level Five-Year TCO | G1: Category-Level Five-Year TCO | H1: Category-Level Five-Year TCO | I1: Category-Level Five-Year TCO | J1: Category-Level Five-Year TCO | K1: Category-Level Five-Year TCO | L1: Category-Level Five-Year TCO | M1: Category-Level Five-Year TCO | N1: Category-Level Five-Year TCO | O1: Category-Level Five-Year TCO | P1: Category-Level Five-Year TCO | Q1: Category-Level Five-Year TCO | R1: Category-Level Five-Year TCO | S1: Category-Level Five-Year TCO | T1: Category-Level Five-Year TCO | U1: Category-Level Five-Year TCO | V1: Category-Level Five-Year TCO | W1: Category-Level Five-Year TCO | X1: Category-Level Five-Year TCO | Y1: Category-Level Five-Year TCO | Z1: Category-Level Five-Year TCO | AA1: Category-Level Five-Year TCO | AB1: Category-Level Five-Year TCO | AC1: Category-Level Five-Year TCO | AD1: Category-Level Five-Year TCO | AE1: Category-Level Five-Year TCO
A2: Each row is a standalone deployment scenario. Change quantities, sites, device prices, data and battery life in blue columns. | B2: Each row is a standalone deployment scenario. Change quantities, sites, device prices, data and battery life in blue columns. | C2: Each row is a standalone deployment scenario. Change quantities, sites, device prices, data and battery life in blue columns. | D2: Each row is a standalone deployment scenario. Change quantities, sites, device prices, data and battery life in blue columns. | E2: Each row is a standalone deployment scenario. Change quantities, sites, device prices, data and battery life in blue columns. | F2: Each row is a standalone deployment scenario. Change quantities, sites, device prices, data and battery life in blue columns. | G2: Each row is a standalone deployment scenario. Change quantities, sites, device prices, data and battery life in blue columns. | H2: Each row is a standalone deployment scenario. Change quantities, sites, device prices, data and battery life in blue columns. | I2: Each row is a standalone deployment scenario. Change quantities, sites, device prices, data and battery life in blue columns. | J2: Each row is a standalone deployment scenario. Change quantities, sites, device prices, data and battery life in blue columns. | K2: Each row is a standalone deployment scenario. Change quantities, sites, device prices, data and battery life in blue columns. | L2: Each row is a standalone deployment scenario. Change quantities, sites, device prices, data and battery life in blue columns. | M2: Each row is a standalone deployment scenario. Change quantities, sites, device prices, data and battery life in blue columns. | N2: Each row is a standalone deployment scenario. Change quantities, sites, device prices, data and battery life in blue columns. | O2: Each row is a standalone deployment scenario. Change quantities, sites, device prices, data and battery life in blue columns. | P2: Each row is a standalone deployment scenario. Change quantities, sites, device prices, data and battery life in blue columns. | Q2: Each row is a standalone deployment scenario. Change quantities, sites, device prices, data and battery life in blue columns. | R2: Each row is a standalone deployment scenario. Change quantities, sites, device prices, data and battery life in blue columns. | S2: Each row is a standalone deployment scenario. Change quantities, sites, device prices, data and battery life in blue columns. | T2: Each row is a standalone deployment scenario. Change quantities, sites, device prices, data and battery life in blue columns. | U2: Each row is a standalone deployment scenario. Change quantities, sites, device prices, data and battery life in blue columns. | V2: Each row is a standalone deployment scenario. Change quantities, sites, device prices, data and battery life in blue columns. | W2: Each row is a standalone deployment scenario. Change quantities, sites, device prices, data and battery life in blue columns. | X2: Each row is a standalone deployment scenario. Change quantities, sites, device prices, data and battery life in blue columns. | Y2: Each row is a standalone deployment scenario. Change quantities, sites, device prices, data and battery life in blue columns. | Z2: Each row is a standalone deployment scenario. Change quantities, sites, device prices, data and battery life in blue columns. | AA2: Each row is a standalone deployment scenario. Change quantities, sites, device prices, data and battery life in blue columns. | AB2: Each row is a standalone deployment scenario. Change quantities, sites, device prices, data and battery life in blue columns. | AC2: Each row is a standalone deployment scenario. Change quantities, sites, device prices, data and battery life in blue columns. | AD2: Each row is a standalone deployment scenario. Change quantities, sites, device prices, data and battery life in blue columns. | AE2: Each row is a standalone deployment scenario. Change quantities, sites, device prices, data and battery life in blue columns.
A4: Sensor / use case | B4: Deployment archetype | C4: Units | D4: Sites | E4: LoRa HW £/unit | F4: NB HW £/unit | G4: Install £/unit | H4: NB data MB/month | I4: LoRa battery years | J4: NB battery years | K4: LoRa suitability (1–5) | L4: NB suitability (1–5) | M4: Required behaviour / boundary | N4: Technical recommendation | O4: Evidence confidence | P4: LoRa device capex | Q4: LoRa shared infra | R4: LoRa maintenance | S4: LoRa server variable | T4: LoRa TCO | U4: LoRa TCO/unit | V4: NB device & tariff | W4: NB data overage | X4: NB maintenance | Y4: NB TCO | Z4: NB TCO/unit | AA4: LoRa minus NB | AB4: Lower-cost option | AC4: Saving vs higher TCO | AD4: LoRa break-even units/site | AE4: Decision note
A5: IAQ sensors | B5: Indoor multi-site | C5: 1069 | D5: 1 | E5: 180 | F5: 195 | G5: 35 | H5: 14.88 | I5: 5 | J5: 3 | K5: 5 | L5: 4 | M5: Periodic CO₂/VOC/PM/temperature metadata | N5: LoRaWAN for dense estates; NB-IoT for isolated buildings | O5: Medium | P5: =C5*(E5+G5+Assumptions!$B$13) -> 245870 | Q5: =D5*Assumptions!$B$6*(Assumptions!$B$7+Assumptions!$B$8)+Assumptions!$B$5*(D5*Assumptions!$B$6*(Assumptions!$B$9+Assumptions!$B$10)+Assumptions!$B$12) -> 1125.8 | R5: =C5*E5*Assumptions!$B$19/100*Assumptions!$B$5+C5*IF(I5<=Assumptions!$B$5,Assumptions!$B$20,0) -> 56657 | S5: =C5*Assumptions!$B$11*12*Assumptions!$B$5 -> 0 | T5: =IF(COUNT(C5)=0,"",SUM(P5:S5)) -> 303652.8 | U5: =IF(COUNT(C5)=0,"",ROUND(T5/C5,2)) -> 284.05 | V5: =IF(COUNT(C5)=0,"",C5*(F5+G5+Assumptions!$B$18+Assumptions!$B$15+Assumptions!$B$14*12*Assumptions!$B$5)) -> 322303.5 | W5: =IF(COUNT(C5)=0,"",ROUND(C5*MAX(0,H5-Assumptions!$B$16)*12*Assumptions!$B$5*Assumptions!$B$17,2)) -> 0 | X5: =IF(COUNT(C5)=0,"",C5*F5*Assumptions!$B$19/100*Assumptions!$B$5+C5*IF(J5<=Assumptions!$B$5,Assumptions!$B$20,0)) -> 58260.5 | Y5: =IF(COUNT(C5)=0,"",SUM(V5:X5)) -> 380564 | Z5: =IF(COUNT(C5)=0,"",ROUND(Y5/C5,2)) -> 356 | AA5: =IF(COUNT(C5)=0,"",ROUND(T5-Y5,2)) -> -76911.2 | AB5: =IF(COUNT(C5)=0,"Not modelled",IF(OR(K5<=2,L5<=2),"Not decisive",IF(T5<Y5,"LoRaWAN",IF(T5>Y5,"NB-IoT","Tie")))) -> LoRaWAN | AC5: =IF(COUNT(C5)=0,"",ABS(T5-Y5)/MAX(T5,Y5)) -> 0.20209794 | AD5: =IF(COUNT(C5)=0,"",IF((Z5-U5+Q5/C5)<=0,"N/A",ROUND((Q5/D5)/(Z5-U5+Q5/C5),0))) -> 15 | AE5: =IF(COUNT(C5)=0,"Not modelled",IF(OR(K5<=2,L5<=2),"Technical constraint dominates cost",IF(AB5=N5,"Cost and architecture align","Review coverage, power and support model"))) -> Review coverage, power and support model
A6: Parking bay sensors | B6: Outdoor campus / street | D6: 1 | E6: 125 | F6: 140 | G6: 85 | H6: 0.2 | I6: 5 | J6: 4 | K6: 5 | L6: 5 | M6: Occupancy events and health telemetry | N6: LoRaWAN on owned campus; NB-IoT for dispersed street assets | O6: Medium | P6: =C6*(E6+G6+Assumptions!$B$13) -> 0 | Q6: =D6*Assumptions!$B$6*(Assumptions!$B$7+Assumptions!$B$8)+Assumptions!$B$5*(D6*Assumptions!$B$6*(Assumptions!$B$9+Assumptions!$B$10)+Assumptions!$B$12) -> 1125.8 | R6: =C6*E6*Assumptions!$B$19/100*Assumptions!$B$5+C6*IF(I6<=Assumptions!$B$5,Assumptions!$B$20,0) -> 0 | S6: =C6*Assumptions!$B$11*12*Assumptions!$B$5 -> 0 | T6: =IF(COUNT(C6)=0,"",SUM(P6:S6)) | U6: =IF(COUNT(C6)=0,"",ROUND(T6/C6,2)) | V6: =IF(COUNT(C6)=0,"",C6*(F6+G6+Assumptions!$B$18+Assumptions!$B$15+Assumptions!$B$14*12*Assumptions!$B$5)) | W6: =IF(COUNT(C6)=0,"",ROUND(C6*MAX(0,H6-Assumptions!$B$16)*12*Assumptions!$B$5*Assumptions!$B$17,2)) | X6: =IF(COUNT(C6)=0,"",C6*F6*Assumptions!$B$19/100*Assumptions!$B$5+C6*IF(J6<=Assumptions!$B$5,Assumptions!$B$20,0)) | Y6: =IF(COUNT(C6)=0,"",SUM(V6:X6)) | Z6: =IF(COUNT(C6)=0,"",ROUND(Y6/C6,2)) | AA6: =IF(COUNT(C6)=0,"",ROUND(T6-Y6,2)) | AB6: =IF(COUNT(C6)=0,"Not modelled",IF(OR(K6<=2,L6<=2),"Not decisive",IF(T6<Y6,"LoRaWAN",IF(T6>Y6,"NB-IoT","Tie")))) -> Not modelled | AC6: =IF(COUNT(C6)=0,"",ABS(T6-Y6)/MAX(T6,Y6)) | AD6: =IF(COUNT(C6)=0,"",IF((Z6-U6+Q6/C6)<=0,"N/A",ROUND((Q6/D6)/(Z6-U6+Q6/C6),0))) | AE6: =IF(COUNT(C6)=0,"Not modelled",IF(OR(K6<=2,L6<=2),"Technical constraint dominates cost",IF(AB6=N6,"Cost and architecture align","Review coverage, power and support model"))) -> Not modelled
A7: Room displays | B7: Indoor rooms | D7: 1 | E7: 200 | F7: 220 | G7: 50 | H7: 0.5 | I7: 99 | J7: 99 | K7: 3 | L7: 3 | M7: E-ink/status updates only; not rich interactive content | N7: LoRaWAN for simple e-ink; Wi-Fi/Ethernet for rich displays | O7: Low | P7: =C7*(E7+G7+Assumptions!$B$13) -> 0 | Q7: =D7*Assumptions!$B$6*(Assumptions!$B$7+Assumptions!$B$8)+Assumptions!$B$5*(D7*Assumptions!$B$6*(Assumptions!$B$9+Assumptions!$B$10)+Assumptions!$B$12) -> 1125.8 | R7: =C7*E7*Assumptions!$B$19/100*Assumptions!$B$5+C7*IF(I7<=Assumptions!$B$5,Assumptions!$B$20,0) -> 0 | S7: =C7*Assumptions!$B$11*12*Assumptions!$B$5 -> 0 | T7: =IF(COUNT(C7)=0,"",SUM(P7:S7)) | U7: =IF(COUNT(C7)=0,"",ROUND(T7/C7,2)) | V7: =IF(COUNT(C7)=0,"",C7*(F7+G7+Assumptions!$B$18+Assumptions!$B$15+Assumptions!$B$14*12*Assumptions!$B$5)) | W7: =IF(COUNT(C7)=0,"",ROUND(C7*MAX(0,H7-Assumptions!$B$16)*12*Assumptions!$B$5*Assumptions!$B$17,2)) | X7: =IF(COUNT(C7)=0,"",C7*F7*Assumptions!$B$19/100*Assumptions!$B$5+C7*IF(J7<=Assumptions!$B$5,Assumptions!$B$20,0)) | Y7: =IF(COUNT(C7)=0,"",SUM(V7:X7)) | Z7: =IF(COUNT(C7)=0,"",ROUND(Y7/C7,2)) | AA7: =IF(COUNT(C7)=0,"",ROUND(T7-Y7,2)) | AB7: =IF(COUNT(C7)=0,"Not modelled",IF(OR(K7<=2,L7<=2),"Not decisive",IF(T7<Y7,"LoRaWAN",IF(T7>Y7,"NB-IoT","Tie")))) -> Not modelled | AC7: =IF(COUNT(C7)=0,"",ABS(T7-Y7)/MAX(T7,Y7)) | AD7: =IF(COUNT(C7)=0,"",IF((Z7-U7+Q7/C7)<=0,"N/A",ROUND((Q7/D7)/(Z7-U7+Q7/C7),0))) | AE7: =IF(COUNT(C7)=0,"Not modelled",IF(OR(K7<=2,L7<=2),"Technical constraint dominates cost",IF(AB7=N7,"Cost and architecture align","Review coverage, power and support model"))) -> Not modelled
A8: Lux sensors | B8: Indoor multi-site | D8: 1 | E8: 70 | F8: 80 | G8: 25 | H8: 0.1 | I8: 8 | J8: 6 | K8: 5 | L8: 4 | M8: Periodic light level and threshold alarms | N8: LoRaWAN where a shared building network exists | O8: Medium | P8: =C8*(E8+G8+Assumptions!$B$13) -> 0 | Q8: =D8*Assumptions!$B$6*(Assumptions!$B$7+Assumptions!$B$8)+Assumptions!$B$5*(D8*Assumptions!$B$6*(Assumptions!$B$9+Assumptions!$B$10)+Assumptions!$B$12) -> 1125.8 | R8: =C8*E8*Assumptions!$B$19/100*Assumptions!$B$5+C8*IF(I8<=Assumptions!$B$5,Assumptions!$B$20,0) -> 0 | S8: =C8*Assumptions!$B$11*12*Assumptions!$B$5 -> 0 | T8: =IF(COUNT(C8)=0,"",SUM(P8:S8)) | U8: =IF(COUNT(C8)=0,"",ROUND(T8/C8,2)) | V8: =IF(COUNT(C8)=0,"",C8*(F8+G8+Assumptions!$B$18+Assumptions!$B$15+Assumptions!$B$14*12*Assumptions!$B$5)) | W8: =IF(COUNT(C8)=0,"",ROUND(C8*MAX(0,H8-Assumptions!$B$16)*12*Assumptions!$B$5*Assumptions!$B$17,2)) | X8: =IF(COUNT(C8)=0,"",C8*F8*Assumptions!$B$19/100*Assumptions!$B$5+C8*IF(J8<=Assumptions!$B$5,Assumptions!$B$20,0)) | Y8: =IF(COUNT(C8)=0,"",SUM(V8:X8)) | Z8: =IF(COUNT(C8)=0,"",ROUND(Y8/C8,2)) | AA8: =IF(COUNT(C8)=0,"",ROUND(T8-Y8,2)) | AB8: =IF(COUNT(C8)=0,"Not modelled",IF(OR(K8<=2,L8<=2),"Not decisive",IF(T8<Y8,"LoRaWAN",IF(T8>Y8,"NB-IoT","Tie")))) -> Not modelled | AC8: =IF(COUNT(C8)=0,"",ABS(T8-Y8)/MAX(T8,Y8)) | AD8: =IF(COUNT(C8)=0,"",IF((Z8-U8+Q8/C8)<=0,"N/A",ROUND((Q8/D8)/(Z8-U8+Q8/C8),0))) | AE8: =IF(COUNT(C8)=0,"Not modelled",IF(OR(K8<=2,L8<=2),"Technical constraint dominates cost",IF(AB8=N8,"Cost and architecture align","Review coverage, power and support model"))) -> Not modelled
A9: Metering — electricity and water | B9: Plantrooms / meters | D9: 1 | E9: 100 | F9: 110 | G9: 75 | H9: 0.3 | I9: 8 | J9: 6 | K9: 5 | L9: 5 | M9: Registers, pulse counts or Modbus data | N9: LoRaWAN for estates; NB-IoT for utility-style dispersed meters | O9: High | P9: =C9*(E9+G9+Assumptions!$B$13) -> 0 | Q9: =D9*Assumptions!$B$6*(Assumptions!$B$7+Assumptions!$B$8)+Assumptions!$B$5*(D9*Assumptions!$B$6*(Assumptions!$B$9+Assumptions!$B$10)+Assumptions!$B$12) -> 1125.8 | R9: =C9*E9*Assumptions!$B$19/100*Assumptions!$B$5+C9*IF(I9<=Assumptions!$B$5,Assumptions!$B$20,0) -> 0 | S9: =C9*Assumptions!$B$11*12*Assumptions!$B$5 -> 0 | T9: =IF(COUNT(C9)=0,"",SUM(P9:S9)) | U9: =IF(COUNT(C9)=0,"",ROUND(T9/C9,2)) | V9: =IF(COUNT(C9)=0,"",C9*(F9+G9+Assumptions!$B$18+Assumptions!$B$15+Assumptions!$B$14*12*Assumptions!$B$5)) | W9: =IF(COUNT(C9)=0,"",ROUND(C9*MAX(0,H9-Assumptions!$B$16)*12*Assumptions!$B$5*Assumptions!$B$17,2)) | X9: =IF(COUNT(C9)=0,"",C9*F9*Assumptions!$B$19/100*Assumptions!$B$5+C9*IF(J9<=Assumptions!$B$5,Assumptions!$B$20,0)) | Y9: =IF(COUNT(C9)=0,"",SUM(V9:X9)) | Z9: =IF(COUNT(C9)=0,"",ROUND(Y9/C9,2)) | AA9: =IF(COUNT(C9)=0,"",ROUND(T9-Y9,2)) | AB9: =IF(COUNT(C9)=0,"Not modelled",IF(OR(K9<=2,L9<=2),"Not decisive",IF(T9<Y9,"LoRaWAN",IF(T9>Y9,"NB-IoT","Tie")))) -> Not modelled | AC9: =IF(COUNT(C9)=0,"",ABS(T9-Y9)/MAX(T9,Y9)) | AD9: =IF(COUNT(C9)=0,"",IF((Z9-U9+Q9/C9)<=0,"N/A",ROUND((Q9/D9)/(Z9-U9+Q9/C9),0))) | AE9: =IF(COUNT(C9)=0,"Not modelled",IF(OR(K9<=2,L9<=2),"Technical constraint dominates cost",IF(AB9=N9,"Cost and architecture align","Review coverage, power and support model"))) -> Not modelled
A10: Fridge / process temperature | B10: Indoor critical assets | D10: 1 | E10: 70 | F10: 76 | G10: 45 | H10: 0.5 | I10: 8 | J10: 6 | K10: 5 | L10: 5 | M10: Periodic temperature plus immediate excursion alarm | N10: Either; preserve local logging and alarm path | O10: High | P10: =C10*(E10+G10+Assumptions!$B$13) -> 0 | Q10: =D10*Assumptions!$B$6*(Assumptions!$B$7+Assumptions!$B$8)+Assumptions!$B$5*(D10*Assumptions!$B$6*(Assumptions!$B$9+Assumptions!$B$10)+Assumptions!$B$12) -> 1125.8 | R10: =C10*E10*Assumptions!$B$19/100*Assumptions!$B$5+C10*IF(I10<=Assumptions!$B$5,Assumptions!$B$20,0) -> 0 | S10: =C10*Assumptions!$B$11*12*Assumptions!$B$5 -> 0 | T10: =IF(COUNT(C10)=0,"",SUM(P10:S10)) | U10: =IF(COUNT(C10)=0,"",ROUND(T10/C10,2)) | V10: =IF(COUNT(C10)=0,"",C10*(F10+G10+Assumptions!$B$18+Assumptions!$B$15+Assumptions!$B$14*12*Assumptions!$B$5)) | W10: =IF(COUNT(C10)=0,"",ROUND(C10*MAX(0,H10-Assumptions!$B$16)*12*Assumptions!$B$5*Assumptions!$B$17,2)) | X10: =IF(COUNT(C10)=0,"",C10*F10*Assumptions!$B$19/100*Assumptions!$B$5+C10*IF(J10<=Assumptions!$B$5,Assumptions!$B$20,0)) | Y10: =IF(COUNT(C10)=0,"",SUM(V10:X10)) | Z10: =IF(COUNT(C10)=0,"",ROUND(Y10/C10,2)) | AA10: =IF(COUNT(C10)=0,"",ROUND(T10-Y10,2)) | AB10: =IF(COUNT(C10)=0,"Not modelled",IF(OR(K10<=2,L10<=2),"Not decisive",IF(T10<Y10,"LoRaWAN",IF(T10>Y10,"NB-IoT","Tie")))) -> Not modelled | AC10: =IF(COUNT(C10)=0,"",ABS(T10-Y10)/MAX(T10,Y10)) | AD10: =IF(COUNT(C10)=0,"",IF((Z10-U10+Q10/C10)<=0,"N/A",ROUND((Q10/D10)/(Z10-U10+Q10/C10),0))) | AE10: =IF(COUNT(C10)=0,"Not modelled",IF(OR(K10<=2,L10<=2),"Technical constraint dominates cost",IF(AB10=N10,"Cost and architecture align","Review coverage, power and support model"))) -> Not modelled
A11: Waste water monitoring | B11: Remote outdoor assets | D11: 1 | E11: 300 | F11: 320 | G11: 250 | H11: 1 | I11: 5 | J11: 4 | K11: 4 | L11: 5 | M11: Level/quality/status metadata; no raw waveforms | N11: NB-IoT usually favoured for dispersed remote assets | O11: Medium | P11: =C11*(E11+G11+Assumptions!$B$13) -> 0 | Q11: =D11*Assumptions!$B$6*(Assumptions!$B$7+Assumptions!$B$8)+Assumptions!$B$5*(D11*Assumptions!$B$6*(Assumptions!$B$9+Assumptions!$B$10)+Assumptions!$B$12) -> 1125.8 | R11: =C11*E11*Assumptions!$B$19/100*Assumptions!$B$5+C11*IF(I11<=Assumptions!$B$5,Assumptions!$B$20,0) -> 0 | S11: =C11*Assumptions!$B$11*12*Assumptions!$B$5 -> 0 | T11: =IF(COUNT(C11)=0,"",SUM(P11:S11)) | U11: =IF(COUNT(C11)=0,"",ROUND(T11/C11,2)) | V11: =IF(COUNT(C11)=0,"",C11*(F11+G11+Assumptions!$B$18+Assumptions!$B$15+Assumptions!$B$14*12*Assumptions!$B$5)) | W11: =IF(COUNT(C11)=0,"",ROUND(C11*MAX(0,H11-Assumptions!$B$16)*12*Assumptions!$B$5*Assumptions!$B$17,2)) | X11: =IF(COUNT(C11)=0,"",C11*F11*Assumptions!$B$19/100*Assumptions!$B$5+C11*IF(J11<=Assumptions!$B$5,Assumptions!$B$20,0)) | Y11: =IF(COUNT(C11)=0,"",SUM(V11:X11)) | Z11: =IF(COUNT(C11)=0,"",ROUND(Y11/C11,2)) | AA11: =IF(COUNT(C11)=0,"",ROUND(T11-Y11,2)) | AB11: =IF(COUNT(C11)=0,"Not modelled",IF(OR(K11<=2,L11<=2),"Not decisive",IF(T11<Y11,"LoRaWAN",IF(T11>Y11,"NB-IoT","Tie")))) -> Not modelled | AC11: =IF(COUNT(C11)=0,"",ABS(T11-Y11)/MAX(T11,Y11)) | AD11: =IF(COUNT(C11)=0,"",IF((Z11-U11+Q11/C11)<=0,"N/A",ROUND((Q11/D11)/(Z11-U11+Q11/C11),0))) | AE11: =IF(COUNT(C11)=0,"Not modelled",IF(OR(K11<=2,L11<=2),"Technical constraint dominates cost",IF(AB11=N11,"Cost and architecture align","Review coverage, power and support model"))) -> Not modelled
A12: Water temperature | B12: Remote / plantroom | D12: 1 | E12: 85 | F12: 95 | G12: 70 | H12: 0.3 | I12: 8 | J12: 6 | K12: 5 | L12: 5 | M12: Periodic readings and threshold alarms | N12: Either; LoRaWAN when sites share coverage | O12: High | P12: =C12*(E12+G12+Assumptions!$B$13) -> 0 | Q12: =D12*Assumptions!$B$6*(Assumptions!$B$7+Assumptions!$B$8)+Assumptions!$B$5*(D12*Assumptions!$B$6*(Assumptions!$B$9+Assumptions!$B$10)+Assumptions!$B$12) -> 1125.8 | R12: =C12*E12*Assumptions!$B$19/100*Assumptions!$B$5+C12*IF(I12<=Assumptions!$B$5,Assumptions!$B$20,0) -> 0 | S12: =C12*Assumptions!$B$11*12*Assumptions!$B$5 -> 0 | T12: =IF(COUNT(C12)=0,"",SUM(P12:S12)) | U12: =IF(COUNT(C12)=0,"",ROUND(T12/C12,2)) | V12: =IF(COUNT(C12)=0,"",C12*(F12+G12+Assumptions!$B$18+Assumptions!$B$15+Assumptions!$B$14*12*Assumptions!$B$5)) | W12: =IF(COUNT(C12)=0,"",ROUND(C12*MAX(0,H12-Assumptions!$B$16)*12*Assumptions!$B$5*Assumptions!$B$17,2)) | X12: =IF(COUNT(C12)=0,"",C12*F12*Assumptions!$B$19/100*Assumptions!$B$5+C12*IF(J12<=Assumptions!$B$5,Assumptions!$B$20,0)) | Y12: =IF(COUNT(C12)=0,"",SUM(V12:X12)) | Z12: =IF(COUNT(C12)=0,"",ROUND(Y12/C12,2)) | AA12: =IF(COUNT(C12)=0,"",ROUND(T12-Y12,2)) | AB12: =IF(COUNT(C12)=0,"Not modelled",IF(OR(K12<=2,L12<=2),"Not decisive",IF(T12<Y12,"LoRaWAN",IF(T12>Y12,"NB-IoT","Tie")))) -> Not modelled | AC12: =IF(COUNT(C12)=0,"",ABS(T12-Y12)/MAX(T12,Y12)) | AD12: =IF(COUNT(C12)=0,"",IF((Z12-U12+Q12/C12)<=0,"N/A",ROUND((Q12/D12)/(Z12-U12+Q12/C12),0))) | AE12: =IF(COUNT(C12)=0,"Not modelled",IF(OR(K12<=2,L12<=2),"Technical constraint dominates cost",IF(AB12=N12,"Cost and architecture align","Review coverage, power and support model"))) -> Not modelled
A13: Water flow | B13: Remote / plantroom | D13: 1 | E13: 100 | F13: 110 | G13: 90 | H13: 0.5 | I13: 8 | J13: 6 | K13: 5 | L13: 5 | M13: Pulse/flow total and anomaly alarm | N13: Either; NB-IoT is simpler when widely dispersed | O13: High | P13: =C13*(E13+G13+Assumptions!$B$13) -> 0 | Q13: =D13*Assumptions!$B$6*(Assumptions!$B$7+Assumptions!$B$8)+Assumptions!$B$5*(D13*Assumptions!$B$6*(Assumptions!$B$9+Assumptions!$B$10)+Assumptions!$B$12) -> 1125.8 | R13: =C13*E13*Assumptions!$B$19/100*Assumptions!$B$5+C13*IF(I13<=Assumptions!$B$5,Assumptions!$B$20,0) -> 0 | S13: =C13*Assumptions!$B$11*12*Assumptions!$B$5 -> 0 | T13: =IF(COUNT(C13)=0,"",SUM(P13:S13)) | U13: =IF(COUNT(C13)=0,"",ROUND(T13/C13,2)) | V13: =IF(COUNT(C13)=0,"",C13*(F13+G13+Assumptions!$B$18+Assumptions!$B$15+Assumptions!$B$14*12*Assumptions!$B$5)) | W13: =IF(COUNT(C13)=0,"",ROUND(C13*MAX(0,H13-Assumptions!$B$16)*12*Assumptions!$B$5*Assumptions!$B$17,2)) | X13: =IF(COUNT(C13)=0,"",C13*F13*Assumptions!$B$19/100*Assumptions!$B$5+C13*IF(J13<=Assumptions!$B$5,Assumptions!$B$20,0)) | Y13: =IF(COUNT(C13)=0,"",SUM(V13:X13)) | Z13: =IF(COUNT(C13)=0,"",ROUND(Y13/C13,2)) | AA13: =IF(COUNT(C13)=0,"",ROUND(T13-Y13,2)) | AB13: =IF(COUNT(C13)=0,"Not modelled",IF(OR(K13<=2,L13<=2),"Not decisive",IF(T13<Y13,"LoRaWAN",IF(T13>Y13,"NB-IoT","Tie")))) -> Not modelled | AC13: =IF(COUNT(C13)=0,"",ABS(T13-Y13)/MAX(T13,Y13)) | AD13: =IF(COUNT(C13)=0,"",IF((Z13-U13+Q13/C13)<=0,"N/A",ROUND((Q13/D13)/(Z13-U13+Q13/C13),0))) | AE13: =IF(COUNT(C13)=0,"Not modelled",IF(OR(K13<=2,L13<=2),"Technical constraint dominates cost",IF(AB13=N13,"Cost and architecture align","Review coverage, power and support model"))) -> Not modelled
A14: Water leak detection | B14: Indoor dense estate | D14: 1 | E14: 65 | F14: 75 | G14: 30 | H14: 0.1 | I14: 5 | J14: 4 | K14: 5 | L14: 5 | M14: Immediate event; local shut-off must not depend on cloud | N14: LoRaWAN for density; NB-IoT for standalone premises | O14: High | P14: =C14*(E14+G14+Assumptions!$B$13) -> 0 | Q14: =D14*Assumptions!$B$6*(Assumptions!$B$7+Assumptions!$B$8)+Assumptions!$B$5*(D14*Assumptions!$B$6*(Assumptions!$B$9+Assumptions!$B$10)+Assumptions!$B$12) -> 1125.8 | R14: =C14*E14*Assumptions!$B$19/100*Assumptions!$B$5+C14*IF(I14<=Assumptions!$B$5,Assumptions!$B$20,0) -> 0 | S14: =C14*Assumptions!$B$11*12*Assumptions!$B$5 -> 0 | T14: =IF(COUNT(C14)=0,"",SUM(P14:S14)) | U14: =IF(COUNT(C14)=0,"",ROUND(T14/C14,2)) | V14: =IF(COUNT(C14)=0,"",C14*(F14+G14+Assumptions!$B$18+Assumptions!$B$15+Assumptions!$B$14*12*Assumptions!$B$5)) | W14: =IF(COUNT(C14)=0,"",ROUND(C14*MAX(0,H14-Assumptions!$B$16)*12*Assumptions!$B$5*Assumptions!$B$17,2)) | X14: =IF(COUNT(C14)=0,"",C14*F14*Assumptions!$B$19/100*Assumptions!$B$5+C14*IF(J14<=Assumptions!$B$5,Assumptions!$B$20,0)) | Y14: =IF(COUNT(C14)=0,"",SUM(V14:X14)) | Z14: =IF(COUNT(C14)=0,"",ROUND(Y14/C14,2)) | AA14: =IF(COUNT(C14)=0,"",ROUND(T14-Y14,2)) | AB14: =IF(COUNT(C14)=0,"Not modelled",IF(OR(K14<=2,L14<=2),"Not decisive",IF(T14<Y14,"LoRaWAN",IF(T14>Y14,"NB-IoT","Tie")))) -> Not modelled | AC14: =IF(COUNT(C14)=0,"",ABS(T14-Y14)/MAX(T14,Y14)) | AD14: =IF(COUNT(C14)=0,"",IF((Z14-U14+Q14/C14)<=0,"N/A",ROUND((Q14/D14)/(Z14-U14+Q14/C14),0))) | AE14: =IF(COUNT(C14)=0,"Not modelled",IF(OR(K14<=2,L14<=2),"Technical constraint dominates cost",IF(AB14=N14,"Cost and architecture align","Review coverage, power and support model"))) -> Not modelled
A15: Acoustic sensors | B15: Water / machinery | D15: 1 | E15: 150 | F15: 165 | G15: 80 | H15: 2 | I15: 5 | J15: 4 | K15: 4 | L15: 5 | M15: Edge-derived dB/features only; raw audio is unsuitable | N15: NB-IoT for dispersed water loggers; either on campus | O15: Medium | P15: =C15*(E15+G15+Assumptions!$B$13) -> 0 | Q15: =D15*Assumptions!$B$6*(Assumptions!$B$7+Assumptions!$B$8)+Assumptions!$B$5*(D15*Assumptions!$B$6*(Assumptions!$B$9+Assumptions!$B$10)+Assumptions!$B$12) -> 1125.8 | R15: =C15*E15*Assumptions!$B$19/100*Assumptions!$B$5+C15*IF(I15<=Assumptions!$B$5,Assumptions!$B$20,0) -> 0 | S15: =C15*Assumptions!$B$11*12*Assumptions!$B$5 -> 0 | T15: =IF(COUNT(C15)=0,"",SUM(P15:S15)) | U15: =IF(COUNT(C15)=0,"",ROUND(T15/C15,2)) | V15: =IF(COUNT(C15)=0,"",C15*(F15+G15+Assumptions!$B$18+Assumptions!$B$15+Assumptions!$B$14*12*Assumptions!$B$5)) | W15: =IF(COUNT(C15)=0,"",ROUND(C15*MAX(0,H15-Assumptions!$B$16)*12*Assumptions!$B$5*Assumptions!$B$17,2)) | X15: =IF(COUNT(C15)=0,"",C15*F15*Assumptions!$B$19/100*Assumptions!$B$5+C15*IF(J15<=Assumptions!$B$5,Assumptions!$B$20,0)) | Y15: =IF(COUNT(C15)=0,"",SUM(V15:X15)) | Z15: =IF(COUNT(C15)=0,"",ROUND(Y15/C15,2)) | AA15: =IF(COUNT(C15)=0,"",ROUND(T15-Y15,2)) | AB15: =IF(COUNT(C15)=0,"Not modelled",IF(OR(K15<=2,L15<=2),"Not decisive",IF(T15<Y15,"LoRaWAN",IF(T15>Y15,"NB-IoT","Tie")))) -> Not modelled | AC15: =IF(COUNT(C15)=0,"",ABS(T15-Y15)/MAX(T15,Y15)) | AD15: =IF(COUNT(C15)=0,"",IF((Z15-U15+Q15/C15)<=0,"N/A",ROUND((Q15/D15)/(Z15-U15+Q15/C15),0))) | AE15: =IF(COUNT(C15)=0,"Not modelled",IF(OR(K15<=2,L15<=2),"Technical constraint dominates cost",IF(AB15=N15,"Cost and architecture align","Review coverage, power and support model"))) -> Not modelled
A16: Bin fill level — ultrasonic | B16: Distributed bins | D16: 1 | E16: 124 | F16: 124 | G16: 75 | H16: 0.2 | I16: 8 | J16: 6 | K16: 5 | L16: 5 | M16: Distance/fill percentage and alarms | N16: NB-IoT for citywide assets; LoRaWAN on campus/private estate | O16: High | P16: =C16*(E16+G16+Assumptions!$B$13) -> 0 | Q16: =D16*Assumptions!$B$6*(Assumptions!$B$7+Assumptions!$B$8)+Assumptions!$B$5*(D16*Assumptions!$B$6*(Assumptions!$B$9+Assumptions!$B$10)+Assumptions!$B$12) -> 1125.8 | R16: =C16*E16*Assumptions!$B$19/100*Assumptions!$B$5+C16*IF(I16<=Assumptions!$B$5,Assumptions!$B$20,0) -> 0 | S16: =C16*Assumptions!$B$11*12*Assumptions!$B$5 -> 0 | T16: =IF(COUNT(C16)=0,"",SUM(P16:S16)) | U16: =IF(COUNT(C16)=0,"",ROUND(T16/C16,2)) | V16: =IF(COUNT(C16)=0,"",C16*(F16+G16+Assumptions!$B$18+Assumptions!$B$15+Assumptions!$B$14*12*Assumptions!$B$5)) | W16: =IF(COUNT(C16)=0,"",ROUND(C16*MAX(0,H16-Assumptions!$B$16)*12*Assumptions!$B$5*Assumptions!$B$17,2)) | X16: =IF(COUNT(C16)=0,"",C16*F16*Assumptions!$B$19/100*Assumptions!$B$5+C16*IF(J16<=Assumptions!$B$5,Assumptions!$B$20,0)) | Y16: =IF(COUNT(C16)=0,"",SUM(V16:X16)) | Z16: =IF(COUNT(C16)=0,"",ROUND(Y16/C16,2)) | AA16: =IF(COUNT(C16)=0,"",ROUND(T16-Y16,2)) | AB16: =IF(COUNT(C16)=0,"Not modelled",IF(OR(K16<=2,L16<=2),"Not decisive",IF(T16<Y16,"LoRaWAN",IF(T16>Y16,"NB-IoT","Tie")))) -> Not modelled | AC16: =IF(COUNT(C16)=0,"",ABS(T16-Y16)/MAX(T16,Y16)) | AD16: =IF(COUNT(C16)=0,"",IF((Z16-U16+Q16/C16)<=0,"N/A",ROUND((Q16/D16)/(Z16-U16+Q16/C16),0))) | AE16: =IF(COUNT(C16)=0,"Not modelled",IF(OR(K16<=2,L16<=2),"Technical constraint dominates cost",IF(AB16=N16,"Cost and architecture align","Review coverage, power and support model"))) -> Not modelled
A17: Optical bin sensors / computer vision | B17: Distributed bins | D17: 1 | E17: 450 | F17: 475 | G17: 180 | H17: 5 | I17: 4 | J17: 3 | K17: 2 | L17: 2 | M17: On-device inference only; do not send images over LPWAN | N17: Use LTE-M/LTE/5G if images are required; LPWAN only for metadata | O17: Low | P17: =C17*(E17+G17+Assumptions!$B$13) -> 0 | Q17: =D17*Assumptions!$B$6*(Assumptions!$B$7+Assumptions!$B$8)+Assumptions!$B$5*(D17*Assumptions!$B$6*(Assumptions!$B$9+Assumptions!$B$10)+Assumptions!$B$12) -> 1125.8 | R17: =C17*E17*Assumptions!$B$19/100*Assumptions!$B$5+C17*IF(I17<=Assumptions!$B$5,Assumptions!$B$20,0) -> 0 | S17: =C17*Assumptions!$B$11*12*Assumptions!$B$5 -> 0 | T17: =IF(COUNT(C17)=0,"",SUM(P17:S17)) | U17: =IF(COUNT(C17)=0,"",ROUND(T17/C17,2)) | V17: =IF(COUNT(C17)=0,"",C17*(F17+G17+Assumptions!$B$18+Assumptions!$B$15+Assumptions!$B$14*12*Assumptions!$B$5)) | W17: =IF(COUNT(C17)=0,"",ROUND(C17*MAX(0,H17-Assumptions!$B$16)*12*Assumptions!$B$5*Assumptions!$B$17,2)) | X17: =IF(COUNT(C17)=0,"",C17*F17*Assumptions!$B$19/100*Assumptions!$B$5+C17*IF(J17<=Assumptions!$B$5,Assumptions!$B$20,0)) | Y17: =IF(COUNT(C17)=0,"",SUM(V17:X17)) | Z17: =IF(COUNT(C17)=0,"",ROUND(Y17/C17,2)) | AA17: =IF(COUNT(C17)=0,"",ROUND(T17-Y17,2)) | AB17: =IF(COUNT(C17)=0,"Not modelled",IF(OR(K17<=2,L17<=2),"Not decisive",IF(T17<Y17,"LoRaWAN",IF(T17>Y17,"NB-IoT","Tie")))) -> Not modelled | AC17: =IF(COUNT(C17)=0,"",ABS(T17-Y17)/MAX(T17,Y17)) | AD17: =IF(COUNT(C17)=0,"",IF((Z17-U17+Q17/C17)<=0,"N/A",ROUND((Q17/D17)/(Z17-U17+Q17/C17),0))) | AE17: =IF(COUNT(C17)=0,"Not modelled",IF(OR(K17<=2,L17<=2),"Technical constraint dominates cost",IF(AB17=N17,"Cost and architecture align","Review coverage, power and support model"))) -> Not modelled
... A21: People counting / footfall | B21: Entrances / circulation | D21: 1 | E21: 220 | F21: 250 | G21: 120 | H21: 3 | I21: 3 | J21: 3 | K21: 4 | L21: 4 | M21: Transmit aggregate counts and occupancy metadata only; images or video require local processing and higher-bandwidth backhaul | N21: PoE for camera/ToF analytics or continuous counts; LPWAN only for privacy-preserving aggregate count metadata | O21: Medium | P21: =C21*(E21+G21+Assumptions!$B$13) -> 0 | Q21: =D21*Assumptions!$B$6*(Assumptions!$B$7+Assumptions!$B$8)+Assumptions!$B$5*(D21*Assumptions!$B$6*(Assumptions!$B$9+Assumptions!$B$10)+Assumptions!$B$12) -> 1125.8 | R21: =C21*E21*Assumptions!$B$19/100*Assumptions!$B$5+C21*IF(I21<=Assumptions!$B$5,Assumptions!$B$20,0) -> 0 | S21: =C21*Assumptions!$B$11*12*Assumptions!$B$5 -> 0 | T21: =IF(COUNT(C21)=0,"",SUM(P21:S21)) | U21: =IF(COUNT(C21)=0,"",ROUND(T21/C21,2)) | V21: =IF(COUNT(C21)=0,"",C21*(F21+G21+Assumptions!$B$18+Assumptions!$B$15+Assumptions!$B$14*12*Assumptions!$B$5)) | W21: =IF(COUNT(C21)=0,"",ROUND(C21*MAX(0,H21-Assumptions!$B$16)*12*Assumptions!$B$5*Assumptions!$B$17,2)) | X21: =IF(COUNT(C21)=0,"",C21*F21*Assumptions!$B$19/100*Assumptions!$B$5+C21*IF(J21<=Assumptions!$B$5,Assumptions!$B$20,0)) | Y21: =IF(COUNT(C21)=0,"",SUM(V21:X21)) | Z21: =IF(COUNT(C21)=0,"",ROUND(Y21/C21,2)) | AA21: =IF(COUNT(C21)=0,"",ROUND(T21-Y21,2)) | AB21: =IF(COUNT(C21)=0,"Not modelled",IF(OR(K21<=2,L21<=2),"Not decisive",IF(T21<Y21,"LoRaWAN",IF(T21>Y21,"NB-IoT","Tie")))) -> Not modelled | AC21: =IF(COUNT(C21)=0,"",ABS(T21-Y21)/MAX(T21,Y21)) | AD21: =IF(COUNT(C21)=0,"",IF((Z21-U21+Q21/C21)<=0,"N/A",ROUND((Q21/D21)/(Z21-U21+Q21/C21),0))) | AE21: =IF(COUNT(C21)=0,"Not modelled",IF(OR(K21<=2,L21<=2),"Technical constraint dominates cost",IF(AB21=N21,"Cost and architecture align","Review coverage, power and support model"))) -> Not modelled

Sheet Sources
A1: Sources & Evidence Log | B1: Sources & Evidence Log | C1: Sources & Evidence Log | D1: Sources & Evidence Log | E1: Sources & Evidence Log | F1: Sources & Evidence Log
A2: Public sources support the benchmark and technical boundaries. Vendor quotations should replace indicative prices before procurement. | B2: Public sources support the benchmark and technical boundaries. Vendor quotations should replace indicative prices before procurement. | C2: Public sources support the benchmark and technical boundaries. Vendor quotations should replace indicative prices before procurement. | D2: Public sources support the benchmark and technical boundaries. Vendor quotations should replace indicative prices before procurement. | E2: Public sources support the benchmark and technical boundaries. Vendor quotations should replace indicative prices before procurement. | F2: Public sources support the benchmark and technical boundaries. Vendor quotations should replace indicative prices before procurement.
A4: Topic | B4: Evidence used | C4: URL | D4: Accessed | E4: Type | F4: Model impact
A5: NB-IoT tariff | B5: £0.98/device/month plus £0.70 one-off; includes 17 MB/device/month | D5: =DATE(2026,7,31) -> 46234 | E5: User input | F5: NB recurring connectivity, one-off fee and included-data inputs
A6: NB-IoT overage | B6: £0.01/MB above 17 MB/device/month | D6: =DATE(2026,7,31) -> 46234 | E6: User input | F6: NB monthly data-overage formula
A7: GBP/EUR | B7: ECB reference rate: £0.85388 per €1 on 24 Jul 2026 | C7: https://www.ecb.europa.eu/stats/policy_and_exchange_rates/euro_reference_exchange_rates/html/index.en.html | D7: 46230 | E7: Official | F7: Currency conversion
A8: UK NB-IoT reach | B8: BT/EE announced NB-IoT coverage of 97% of UK population | C8: https://newsroom.bt.com/bt-launches-multi-million-pound-nb-iot-network-to-support-uk-smart-cities/ | D8: 46230 | E8: Operator primary | F8: Supports dispersed-asset option; location testing still required
A9: UK NB-IoT use case | B9: Vodafone NB-IoT supports leak detection without Wi-Fi | C9: https://www.vodafone.co.uk/business/case-studies/leaksafe-and-vodafone-business-narrowband-iot | D9: 46230 | E9: Operator primary | F9: Leak detection fit
A10: Acoustic water logging | B10: Vodafone says NB-IoT improved underground reach and power versus 3G/4G | C10: https://www.vodafone.co.uk/business/case-studies/nb-iot-gutermann | D10: 46230 | E10: Operator primary | F10: Acoustic/dispersed water fit
A11: NB-IoT bandwidth boundary | B11: Vodafone describes NB-IoT as supporting small amounts of data | C11: https://www.vodafone.co.uk/business/iot/iot-faqs | D11: 46230 | E11: Operator primary | F11: Excludes video/raw high-rate data
A12: LoRaWAN smart buildings | B12: LoRa Alliance identifies environmental, leak, occupancy, metering and predictive-maintenance applications | C12: https://lora-alliance.org/buildings-vertical-market/ | D12: 46230 | E12: Industry body | F12: Building/campus suitability
A13: LoRaWAN/NB-IoT comparison | B13: LoRaWAN evidence for smart buildings and utilities | C13: https://lora-alliance.org/wp-content/uploads/2020/11/cr-lora-102_lorawanr_and_nb-iot.pdf | D13: 46230 | E13: Industry white paper | F13: Category fit scoring
A14: LoRa gateway | B14: UG65 supports indoor deployments and up to 2,000 devices | C14: https://www.milesight.com/iot/product/lorawan-gateway/ug65 | D14: 46230 | E14: Vendor primary | F14: Gateway capacity assumption
A15: UK device/gateway pricing | B15: Public UK prices for LoRaWAN, NB-IoT sensors and gateways | C15: https://ukiot.io/shop/ | D15: 46230 | E15: Distributor | F15: Hardware planning benchmarks
A16: LoRaWAN server | B16: The Things Stack provides managed cloud and free discovery tier | C16: https://www.thethingsindustries.com/stack/plans/ | D16: 46230 | E16: Vendor primary | F16: Network-server architecture
A17: LoRaWAN server price anchor | B17: AWS Marketplace lists $0.336/hour to register up to 1,000 devices | C17: https://aws.amazon.com/marketplace/pp/prodview-djx65iyt6w5cy | D17: 46230 | E17: Marketplace | F17: £0.20/device/month planning benchmark at scale
A18: LPWA comparison | B18: GSMA compares bandwidth, latency, battery, spectrum and module cost across NB-IoT and LoRaWAN | C18: https://www.gsma.com/solutions-and-impact/connectivity-for-good/mobile-for-development/wp-content/uploads/2023/04/IoT-for-Development-Use-cases-delivering-impact.pdf | D18: 46230 | E18: Industry body | F18: Technical decision gates
... A21: People counting privacy | B21: Video surveillance that processes personal data requires data protection by design, fairness, accountability and transparency | C21: https://ico.org.uk/for-organisations/uk-gdpr-guidance-and-resources/cctv-and-video-surveillance/guidance-on-video-surveillance-including-cctv/about-this-guidance/ | D21: 46234 | E21: UK regulator | F21: People-counting decision boundary and privacy-by-design recommendation

Sheet PoE Model
A1: PoE Category-Level Five-Year TCO
A2: PoE is a wired power-and-data architecture. Each row links to the corresponding deployment quantity and site count in Category Model; edit the blue PoE inputs below.
A4: Sensor / use case | B4: Deployment archetype | C4: Units | D4: Sites | E4: PoE HW £/unit | F4: Cabling & install £/unit | G4: Average W/device | H4: PoE suitability (1–5) | I4: Required behaviour / boundary | J4: PoE technical recommendation | K4: Confidence | L4: Endpoint capex | M4: Shared network | N4: Energy, support & maintenance | O4: PoE TCO | P4: PoE TCO/unit
A5: ='Category Model'!A5 -> IAQ sensors | B5: ='Category Model'!B5 -> Indoor multi-site | C5: ='Category Model'!C5 -> 1069 | D5: ='Category Model'!D5 -> 1 | E5: 190 | F5: 50 | G5: 4 | H5: 5 | I5: Continuous power and IP data suit fixed indoor IAQ endpoints | J5: PoE is attractive where structured cabling exists; LPWAN remains simpler for retrofit or dispersed sites | K5: High | L5: =IF(COUNT('Category Model'!C5)=0,"",C5*(E5+F5+Assumptions!$B$25)) -> 277940 | M5: =IF(COUNT('Category Model'!C5)=0,"",D5*(Assumptions!$B$22+Assumptions!$B$23)) -> 0 | N5: =IF(COUNT('Category Model'!C5)=0,"",ROUND(C5*G5/1000*8760*Assumptions!$B$26/Assumptions!$B$27*Assumptions!$B$5+D5*Assumptions!$B$24*Assumptions!$B$5+C5*E5*Assumptions!$B$28/100*Assumptions!$B$5,2)) -> 58369.18 | O5: =IF(COUNT('Category Model'!C5)=0,"",ROUND(SUM(L5:N5),2)) -> 336309.18 | P5: =IF(COUNT('Category Model'!C5)=0,"",ROUND(O5/C5,2)) -> 314.6
A6: ='Category Model'!A6 -> Parking bay sensors | B6: ='Category Model'!B6 -> Outdoor campus / street | C6: ='Category Model'!C6 -> 0 | D6: ='Category Model'!D6 -> 1 | E6: 160 | F6: 350 | G6: 3 | H6: 2 | I6: Outdoor bay devices need protected cabling and civil works | J6: Use PoE only where ducts and nearby network cabinets already exist | K6: Low | L6: =IF(COUNT('Category Model'!C6)=0,"",C6*(E6+F6+Assumptions!$B$25)) | M6: =IF(COUNT('Category Model'!C6)=0,"",D6*(Assumptions!$B$22+Assumptions!$B$23)) | N6: =IF(COUNT('Category Model'!C6)=0,"",ROUND(C6*G6/1000*8760*Assumptions!$B$26/Assumptions!$B$27*Assumptions!$B$5+D6*Assumptions!$B$24*Assumptions!$B$5+C6*E6*Assumptions!$B$28/100*Assumptions!$B$5,2)) | O6: =IF(COUNT('Category Model'!C6)=0,"",ROUND(SUM(L6:N6),2)) | P6: =IF(COUNT('Category Model'!C6)=0,"",ROUND(O6/C6,2))
A7: ='Category Model'!A7 -> Room displays | B7: ='Category Model'!B7 -> Indoor rooms | C7: ='Category Model'!C7 -> 0 | D7: ='Category Model'!D7 -> 1 | E7: 240 | F7: 160 | G7: 12 | H7: 5 | I7: Rich displays benefit from continuous power and Ethernet bandwidth | J7: PoE is preferred for interactive or frequently updated room displays | K7: High | L7: =IF(COUNT('Category Model'!C7)=0,"",C7*(E7+F7+Assumptions!$B$25)) | M7: =IF(COUNT('Category Model'!C7)=0,"",D7*(Assumptions!$B$22+Assumptions!$B$23)) | N7: =IF(COUNT('Category Model'!C7)=0,"",ROUND(C7*G7/1000*8760*Assumptions!$B$26/Assumptions!$B$27*Assumptions!$B$5+D7*Assumptions!$B$24*Assumptions!$B$5+C7*E7*Assumptions!$B$28/100*Assumptions!$B$5,2)) | O7: =IF(COUNT('Category Model'!C7)=0,"",ROUND(SUM(L7:N7),2)) | P7: =IF(COUNT('Category Model'!C7)=0,"",ROUND(O7/C7,2))
A8: ='Category Model'!A8 -> Lux sensors | B8: ='Category Model'!B8 -> Indoor multi-site | C8: ='Category Model'!C8 -> 0 | D8: ='Category Model'!D8 -> 1 | E8: 85 | F8: 150 | G8: 2 | H8: 5 | I8: Fixed ceiling/wall sensors are compatible with structured cabling | J8: PoE is strong in new-build or refurbished estates with spare ports | K8: High | L8: =IF(COUNT('Category Model'!C8)=0,"",C8*(E8+F8+Assumptions!$B$25)) | M8: =IF(COUNT('Category Model'!C8)=0,"",D8*(Assumptions!$B$22+Assumptions!$B$23)) | N8: =IF(COUNT('Category Model'!C8)=0,"",ROUND(C8*G8/1000*8760*Assumptions!$B$26/Assumptions!$B$27*Assumptions!$B$5+D8*Assumptions!$B$24*Assumptions!$B$5+C8*E8*Assumptions!$B$28/100*Assumptions!$B$5,2)) | O8: =IF(COUNT('Category Model'!C8)=0,"",ROUND(SUM(L8:N8),2)) | P8: =IF(COUNT('Category Model'!C8)=0,"",ROUND(O8/C8,2))
